{
  "artifacts": [],
  "command": "run_experiment",
  "experiment": {
    "base_dir": "/cs/grad/pazbu/paz/dev/projects/dnanet-v2",
    "dependencies": [
      "numpy==1.12.1",
      "posixpath==<unknown>",
      "sacred==0.7.0",
      "tensorflow==1.0.1"
    ],
    "mainfile": "train.py",
    "name": "train",
    "repositories": [],
    "sources": [
      [
        "enhancersdata.py",
        "_sources/enhancersdata_21346ea0c0237f911553d568304f39ef.py"
      ],
      [
        "train.py",
        "_sources/train_cfc1c66e3debd8675cf21f8e155c14cf.py"
      ]
    ]
  },
  "fail_trace": [
    "Traceback (most recent call last):\n",
    "  File \"/usr/local/jetbrains/pycharm-2016.2.1/helpers/pydev/_pydevd_bundle/pydevd_frame.py\", line 539, in trace_dispatch\n    self.do_wait_suspend(thread, frame, event, arg)\n",
    "  File \"/usr/local/jetbrains/pycharm-2016.2.1/helpers/pydev/_pydevd_bundle/pydevd_frame.py\", line 71, in do_wait_suspend\n    self._args[0].do_wait_suspend(*args, **kwargs)\n",
    "  File \"/usr/local/jetbrains/pycharm-2016.2.1/helpers/pydev/pydevd.py\", line 714, in do_wait_suspend\n    time.sleep(0.01)\n",
    "KeyboardInterrupt\n",
    "\nDuring handling of the above exception, another exception occurred:\n\n",
    "Traceback (most recent call last):\n",
    "  File \"/cs/cbio/paz/dev/python3.5+tf1/lib/python3.5/site-packages/sacred/config/captured_function.py\", line 47, in captured_function\n    result = wrapped(*args, **kwargs)\n",
    "  File \"/cs/grad/pazbu/paz/dev/projects/dnanet-v2/train.py\", line 77, in run_experiment\n    tf.set_random_seed(seed)\n",
    "  File \"/cs/grad/pazbu/paz/dev/projects/dnanet-v2/train.py\", line 77, in run_experiment\n    tf.set_random_seed(seed)\n",
    "  File \"/usr/local/jetbrains/pycharm-2016.2.1/helpers/pydev/_pydevd_bundle/pydevd_frame.py\", line 543, in trace_dispatch\n    traceback.print_exc()\n",
    "  File \"/usr/lib64/python3.5/traceback.py\", line 159, in print_exc\n    print_exception(*sys.exc_info(), limit=limit, file=file, chain=chain)\n",
    "  File \"/usr/lib64/python3.5/traceback.py\", line 101, in print_exception\n    print(line, file=file, end=\"\")\n",
    "BrokenPipeError: [Errno 32] Broken pipe\n"
  ],
  "heartbeat": "2017-09-10T12:28:11.319316",
  "host": {
    "ENV": {},
    "cpu": "Intel(R) Core(TM) i7-3770 CPU @ 3.40GHz",
    "hostname": "chr-01",
    "os": [
      "Linux",
      "Linux-4.8.4-aufs-1-x86_64-with-debian-stretch-sid"
    ],
    "python_version": "3.5.2+"
  },
  "meta": {
    "command": "run_experiment",
    "options": {
      "--beat_interval": null,
      "--capture": null,
      "--comment": null,
      "--debug": false,
      "--enforce_clean": false,
      "--file_storage": null,
      "--force": false,
      "--help": false,
      "--loglevel": null,
      "--mongo_db": null,
      "--name": null,
      "--pdb": false,
      "--print_config": false,
      "--priority": null,
      "--queue": false,
      "--sql": null,
      "--tiny_db": null,
      "--unobserved": false,
      "COMMAND": null,
      "UPDATE": [],
      "help": false,
      "with": false
    }
  },
  "resources": [],
  "result": null,
  "start_time": "2017-09-10T12:22:26.358673",
  "status": "FAILED",
  "stop_time": "2017-09-10T12:28:11.322593"
}